2023-09-28 22:16:48,728 INFO    StreamThr :51965 [internal.py:wandb_internal():86] W&B internal server running at pid: 51965, started at: 2023-09-28 22:16:48.728160
2023-09-28 22:16:48,729 DEBUG   HandlerThread:51965 [handler.py:handle_request():144] handle_request: status
2023-09-28 22:16:48,729 INFO    WriterThread:51965 [datastore.py:open_for_write():85] open: /Users/oliverclive-griffin/personal/transformer-from-scratch/wandb/run-20230928_221648-pey4lphl/run-pey4lphl.wandb
2023-09-28 22:16:48,731 DEBUG   SenderThread:51965 [sender.py:send():380] send: header
2023-09-28 22:16:48,731 DEBUG   SenderThread:51965 [sender.py:send():380] send: run
2023-09-28 22:16:49,263 ERROR   SenderThread:51965 [internal_api.py:execute():369] 403 response executing GraphQL.
2023-09-28 22:16:49,264 ERROR   SenderThread:51965 [internal_api.py:execute():370] {"errors":[{"message":"permission denied","path":["upsertBucket"],"extensions":{"code":"PERMISSION_ERROR"}}],"data":{"upsertBucket":null}}
2023-09-28 22:16:49,264 ERROR   SenderThread:51965 [sender.py:send_run():977] It appears that you do not have permission to access the requested resource. Please reach out to the project owner to grant you access. If you have the correct permissions, verify that there are no issues with your networking setup.(Error 403: Forbidden)
Traceback (most recent call last):
  File "/Users/oliverclive-griffin/.local/share/virtualenvs/transformer-from-scratch-IzBRPy8T/lib/python3.11/site-packages/wandb/sdk/lib/retry.py", line 131, in __call__
    result = self._call_fn(*args, **kwargs)
             ^^^^^^^^^^^^^^^^^^^^^^^^^^^^^^
  File "/Users/oliverclive-griffin/.local/share/virtualenvs/transformer-from-scratch-IzBRPy8T/lib/python3.11/site-packages/wandb/sdk/internal/internal_api.py", line 366, in execute
    return self.client.execute(*args, **kwargs)  # type: ignore
           ^^^^^^^^^^^^^^^^^^^^^^^^^^^^^^^^^^^^
  File "/Users/oliverclive-griffin/.local/share/virtualenvs/transformer-from-scratch-IzBRPy8T/lib/python3.11/site-packages/wandb/vendor/gql-0.2.0/wandb_gql/client.py", line 52, in execute
    result = self._get_result(document, *args, **kwargs)
             ^^^^^^^^^^^^^^^^^^^^^^^^^^^^^^^^^^^^^^^^^^^
  File "/Users/oliverclive-griffin/.local/share/virtualenvs/transformer-from-scratch-IzBRPy8T/lib/python3.11/site-packages/wandb/vendor/gql-0.2.0/wandb_gql/client.py", line 60, in _get_result
    return self.transport.execute(document, *args, **kwargs)
           ^^^^^^^^^^^^^^^^^^^^^^^^^^^^^^^^^^^^^^^^^^^^^^^^^
  File "/Users/oliverclive-griffin/.local/share/virtualenvs/transformer-from-scratch-IzBRPy8T/lib/python3.11/site-packages/wandb/sdk/lib/gql_request.py", line 59, in execute
    request.raise_for_status()
  File "/Users/oliverclive-griffin/.local/share/virtualenvs/transformer-from-scratch-IzBRPy8T/lib/python3.11/site-packages/requests/models.py", line 1021, in raise_for_status
    raise HTTPError(http_error_msg, response=self)
requests.exceptions.HTTPError: 403 Client Error: Forbidden for url: https://api.wandb.ai/graphql

During handling of the above exception, another exception occurred:

Traceback (most recent call last):
  File "/Users/oliverclive-griffin/.local/share/virtualenvs/transformer-from-scratch-IzBRPy8T/lib/python3.11/site-packages/wandb/sdk/internal/sender.py", line 975, in send_run
    self._init_run(run, config_value_dict)
  File "/Users/oliverclive-griffin/.local/share/virtualenvs/transformer-from-scratch-IzBRPy8T/lib/python3.11/site-packages/wandb/sdk/internal/sender.py", line 1013, in _init_run
    server_run, inserted, server_messages = self._api.upsert_run(
                                            ^^^^^^^^^^^^^^^^^^^^^
  File "/Users/oliverclive-griffin/.local/share/virtualenvs/transformer-from-scratch-IzBRPy8T/lib/python3.11/site-packages/wandb/apis/normalize.py", line 73, in wrapper
    raise err
  File "/Users/oliverclive-griffin/.local/share/virtualenvs/transformer-from-scratch-IzBRPy8T/lib/python3.11/site-packages/wandb/apis/normalize.py", line 41, in wrapper
    return func(*args, **kwargs)
           ^^^^^^^^^^^^^^^^^^^^^
  File "/Users/oliverclive-griffin/.local/share/virtualenvs/transformer-from-scratch-IzBRPy8T/lib/python3.11/site-packages/wandb/sdk/internal/internal_api.py", line 2007, in upsert_run
    response = self.gql(
               ^^^^^^^^^
  File "/Users/oliverclive-griffin/.local/share/virtualenvs/transformer-from-scratch-IzBRPy8T/lib/python3.11/site-packages/wandb/sdk/internal/internal_api.py", line 338, in gql
    ret = self._retry_gql(
          ^^^^^^^^^^^^^^^^
  File "/Users/oliverclive-griffin/.local/share/virtualenvs/transformer-from-scratch-IzBRPy8T/lib/python3.11/site-packages/wandb/sdk/lib/retry.py", line 147, in __call__
    retry_timedelta_triggered = check_retry_fn(e)
                                ^^^^^^^^^^^^^^^^^
  File "/Users/oliverclive-griffin/.local/share/virtualenvs/transformer-from-scratch-IzBRPy8T/lib/python3.11/site-packages/wandb/util.py", line 964, in check_retry_fn
    return fallback_retry_fn(e)
           ^^^^^^^^^^^^^^^^^^^^
  File "/Users/oliverclive-griffin/.local/share/virtualenvs/transformer-from-scratch-IzBRPy8T/lib/python3.11/site-packages/wandb/util.py", line 906, in no_retry_auth
    raise CommError(
wandb.errors.CommError: It appears that you do not have permission to access the requested resource. Please reach out to the project owner to grant you access. If you have the correct permissions, verify that there are no issues with your networking setup.(Error 403: Forbidden)
2023-09-28 22:16:49,455 DEBUG   HandlerThread:51965 [handler.py:handle_request():144] handle_request: shutdown
2023-09-28 22:16:49,455 INFO    HandlerThread:51965 [handler.py:finish():844] shutting down handler
2023-09-28 22:16:49,734 INFO    WriterThread:51965 [datastore.py:close():294] close: /Users/oliverclive-griffin/personal/transformer-from-scratch/wandb/run-20230928_221648-pey4lphl/run-pey4lphl.wandb
2023-09-28 22:16:50,276 INFO    SenderThread:51965 [sender.py:finish():1534] shutting down sender
